Workbook

Sheet Intro
B3: 🟡 Celdas amarillas = INPUTS | H3: 🔵 / 🔴 Outputs (según hoja)
B5: Son las únicas que deberían modificar: | H5: P&L
H6: EBITDA
B7: Pricing (precios / promos) | H7: Caja
B8: DDI / surtido | H8: Alertas
B9: Mix digital
B10: Estrategia logística | H10: 👉 Son el resultado de las decisiones.
B11: Inversión en marketing
B12: Aperturas / cierres (si aplica)
B14: 👉 Representan decisiones estratégicas reales.
B17: 🧠 2. CÓMO FUNCIONA EL SIMULADOR
B19: El modelo replica un negocio real con 5 motores:
B21: 1. 💰 Pricing
B22: 2. 🛒 Surtido / DDI
B23: 3. 📲 Canal Digital
B24: 4. 🚚 Logística
B25: 5. 👤 Clientes (CLV)
B27: Todas sus decisiones impactan en:
B29: 👉 P&L + Flujo de Caja + Riesgo del negocio
B33: ⚙️ 4. QUÉ DECISIONES PUEDEN TOMAR
B37: 💰 Pricing | E37: 🛒 Surtido & DDI | I37: 📲 Canal Digital | L37: 🚚 Logística | O37: 👤 Clientes (CLV)
B39: Subir / bajar precios | E39: Reducir SKUs | I39: % ventas digitales | L39: Modelo fulfillment | O39: Inversión en adquisición vs retención
E40: Ajustar días de inventario | I40: Mix delivery vs pick-up | L40: Nivel de servicio (SLA)
O41: 👉 Impacta:
B42: 👉 Impacta: | E42: 👉 Impacta: | I42: 👉 Impacta: | L42: 👉 Impacta:
O43: frecuencia
B44: volumen | E44: ventas | I44: crecimiento | L44: costo por pedido | O44: churn
B45: margen | E45: capital de trabajo | I45: costos logísticos | L45: experiencia cliente | O45: revenue futuro
E46: quiebres de stock
B50: 💸 5. CÓMO LEER LOS RESULTADOS
B54: 📊 P&L | D54: 💸 Flujo de Caja (CLAVE) | H54: 🚨 Alertas | J54: 🧠 Score de Consistencia
B56: Revenue | D56: EBITDA | H56: Caja negativa | J56: Evalúa si su estrategia tiene sentido:
B57: Margen | D57: Capital de trabajo | H57: CAPEX excedido
B58: EBITDA | D58: CAPEX | J58: pricing vs posicionamiento
J59: surtido vs eficiencia
B60: 👉 Mide rentabilidad | D60: 👉 Mide supervivencia | J60: digital vs logística

Sheet 00_General
B2: PharmaLink 360 - Simulador Integrado de Turnaround Retail & Omnicanalidad
B4: Variable | C4: Valor | E4: Objetivos del caso
B5: Horizonte del simulador | C5: 12 meses | E5: 1 | F5: Construir presupuesto anual de 12 meses
B6: Mes de inicio | C6: Mes 1 | E6: 2 | F6: Diseñar Plan 100 días con quick wins accionables
B7: KPI madre | C7: EBITDA ajustado por Cost-to-Serve + sostenibilidad de caja | E7: 3 | F7: Maximizar EBITDA ajustado por Cost-to-Serve
B8: Punto de partida | C8: Resultado operativo positivo / flujo de caja negativo | E8: 4 | F8: Revertir flujo de caja negativo sin destruir la red
B9: PDV Base | C9: 120
B10: Ventas Mes 0 (ARS MM) | C10: 29984.5 | E10: 5 | F10: Defender decisiones con datos de los simuladores
B11: EBITDA Mes 0 (ARS MM) | C11: 881.125 | D11: =+C11/C10 -> 0.029386016
B12: Caja inicial Mes 0 (ARS MM) | C12: -25000 | E12: Hard constraints
B13: Inventario inicial (ARS MM) | C13: 60000 | E13: CAPEX | F13: No superar presupuesto total
B14: DDI inicial ponderado | C14: 62 | E14: Caja | F14: No más de 3 meses seguidos de FCF negativo
B15: CAPEX máximo (ARS MM) | C15: 50000
B16: Máx. meses consecutivos de FCF negativo | C16: 3
B17: Inflación mensual costos | C17: 0.04
B18: Factor IPC + personal/alquileres | C18: 0.02
B19: FX referencia ARS/USD | C19: 1000

Sheet 01_Master_Variables
B3: Master Variables - capa de integracion unica hacia P&L y Caja
B5: Variable | C5: Mes 0 | D5: Mes 1 | E5: Mes 2 | F5: Mes 3 | G5: Mes 4 | H5: Mes 5 | I5: Mes 6 | J5: Mes 7 | K5: Mes 8 | L5: Mes 9 | M5: Mes 10 | N5: Mes 11 | O5: Mes 12 | P5: TOTAL
B6: Revenue simulado | C6: ='00_General'!C10 -> 29984.5 | D6: =+'03_CatMan_DDI'!D69+'06_Red_CAPEX'!E73+'05_CLV_Marketing'!D50 -> 29368.464 | E6: =+'03_CatMan_DDI'!E69+'06_Red_CAPEX'!F73+'05_CLV_Marketing'!E50 -> 28959.999 | F6: =+'03_CatMan_DDI'!F69+'06_Red_CAPEX'!G73+'05_CLV_Marketing'!F50 -> 29137.949 | G6: =+'03_CatMan_DDI'!G69+'06_Red_CAPEX'!H73+'05_CLV_Marketing'!G50 -> 28569.856 | H6: =+'03_CatMan_DDI'!H69+'06_Red_CAPEX'!I73+'05_CLV_Marketing'!H50 -> 28037.177 | I6: =+'03_CatMan_DDI'!I69+'06_Red_CAPEX'!J73+'05_CLV_Marketing'!I50 -> 28060.276 | J6: =+'03_CatMan_DDI'!J69+'06_Red_CAPEX'!K73+'05_CLV_Marketing'!J50 -> 28257.162 | K6: =+'03_CatMan_DDI'!K69+'06_Red_CAPEX'!L73+'05_CLV_Marketing'!K50 -> 28340.977 | ... O6: =+'03_CatMan_DDI'!O69+'06_Red_CAPEX'!P73+'05_CLV_Marketing'!O50 -> 29507.551 | P6: =SUM(D6:O6) -> 344699.21
B7: Margen bruto % | C7: ='02_Pricing'!I18 -> 0.34171106 | D7: ='02_Pricing'!I18 -> 0.34171106 | E7: ='02_Pricing'!I18 -> 0.34171106 | F7: ='02_Pricing'!I18 -> 0.34171106 | G7: ='02_Pricing'!I18 -> 0.34171106 | H7: ='02_Pricing'!I18 -> 0.34171106 | I7: ='02_Pricing'!I18 -> 0.34171106 | J7: ='02_Pricing'!I18 -> 0.34171106 | K7: ='02_Pricing'!I18 -> 0.34171106 | L7: ='02_Pricing'!I18 -> 0.34171106 | M7: ='02_Pricing'!I18 -> 0.34171106 | N7: ='02_Pricing'!I18 -> 0.34171106 | O7: ='02_Pricing'!I18 -> 0.34171106 | P7: =+P8/P6 -> 0.34171106
B8: Margen bruto | C8: =C6*C7 -> 10246.035 | D8: =D6*D7 -> 10035.529 | E8: =E6*E7 -> 9895.9517 | F8: =F6*F7 -> 9956.7595 | G8: =G6*G7 -> 9762.6358 | H8: =H6*H7 -> 9580.6135 | I8: =I6*I7 -> 9588.5067 | J8: =J6*J7 -> 9655.7847 | ... O8: =O6*O7 -> 10083.057 | P8: =SUM(D8:O8) -> 117787.53
B9: Penetracion digital target | C9: =SUM('04_Digital_Logistica'!C8:C10) -> 0.15643549 | D9: =SUM('04_Digital_Logistica'!D8:D10) -> 0.16719977 | E9: =SUM('04_Digital_Logistica'!E8:E10) -> 0.16772445 | F9: =SUM('04_Digital_Logistica'!F8:F10) -> 0.16749406 | G9: =SUM('04_Digital_Logistica'!G8:G10) -> 0.1682396 | H9: =SUM('04_Digital_Logistica'!H8:H10) -> 0.16896612 | I9: =SUM('04_Digital_Logistica'!I8:I10) -> 0.18755467 | J9: =SUM('04_Digital_Logistica'!J8:J10) -> 0.18715365 | ... P9: =SUM('04_Digital_Logistica'!P8:P10) -> 0.26
B10: Costo logistico | C10: =+'04_Digital_Logistica'!C20 -> 1031.4813 | D10: =+'04_Digital_Logistica'!D20 -> 1020.6711 | E10: =+'04_Digital_Logistica'!E20 -> 1007.539 | F10: =+'04_Digital_Logistica'!F20 -> 1013.2601 | G10: =+'04_Digital_Logistica'!G20 -> 994.99588 | H10: =+'04_Digital_Logistica'!H20 -> 977.87025 | I10: =+'04_Digital_Logistica'!I20 -> 1015.1879 | J10: =+'04_Digital_Logistica'!J20 -> 1021.5178 | ... O10: =+'04_Digital_Logistica'!O20 -> 1171.4428 | P10: =SUM(D10:O10) -> 12584.98
B11: Inventario | C11: =+'03_CatMan_DDI'!C86 -> 41385.114 | D11: =+'03_CatMan_DDI'!D86 -> 35902.136 | E11: =+'03_CatMan_DDI'!E86 -> 35902.136 | F11: =+'03_CatMan_DDI'!F86 -> 35902.136 | G11: =+'03_CatMan_DDI'!G86 -> 35902.136 | H11: =+'03_CatMan_DDI'!H86 -> 35902.136 | I11: =+'03_CatMan_DDI'!I86 -> 35902.136 | J11: =+'03_CatMan_DDI'!J86 -> 35902.136 | ... O11: =+'03_CatMan_DDI'!O86 -> 35902.136 | Q11: Considera que baja a DDI obj en el mes 2 , porque multiplica por 65%
B12: Liberacion / absorcion WC | D12: =C11-D11 -> 5482.9781 | E12: =D11-E11 -> 0 | F12: =E11-F11 -> 0 | G12: =F11-G11 -> 0 | H12: =G11-H11 -> 0 | I12: =H11-I11 -> 0 | J12: =I11-J11 -> 0 | K12: =J11-K11 -> 0 | ... O12: =N11-O11 -> 0 | P12: =SUM(D12:O12) -> 5482.9781
B13: Marketing | C13: =+D13 -> 265.41118 | D13: =+'05_CLV_Marketing'!D57 -> 265.41118 | E13: =+'05_CLV_Marketing'!E57 -> 302.15039 | F13: =+'05_CLV_Marketing'!F57 -> 335.49743 | G13: =+'05_CLV_Marketing'!G57 -> 365.71247 | H13: =+'05_CLV_Marketing'!H57 -> 393.03734 | I13: =+'05_CLV_Marketing'!I57 -> 417.69673 | J13: =+'05_CLV_Marketing'!J57 -> 439.89941 | K13: =+'05_CLV_Marketing'!K57 -> 459.83924 | ... P13: =+'05_CLV_Marketing'!P57 -> 4978.7755
B14: CAPEX | C14: =+'06_Red_CAPEX'!D87 -> 0 | D14: =+'06_Red_CAPEX'!E87 -> 0 | E14: =+'06_Red_CAPEX'!F87 -> 0 | F14: =+'06_Red_CAPEX'!G87 -> 5833.3333 | G14: =+'06_Red_CAPEX'!H87 -> 0 | H14: =+'06_Red_CAPEX'!I87 -> 0 | I14: =+'06_Red_CAPEX'!J87 -> 4400 | J14: =+'06_Red_CAPEX'!K87 -> 5833.3333 | ... P14: =+'06_Red_CAPEX'!Q87 -> 35100
B15: Competitividad | C15: =+'02_Pricing'!C104 -> 100 | D15: =+'02_Pricing'!D104 -> 100 | E15: =+'02_Pricing'!E104 -> 100 | F15: =+'02_Pricing'!F104 -> 100 | G15: =+'02_Pricing'!G104 -> 100 | H15: =+'02_Pricing'!H104 -> 100 | I15: =+'02_Pricing'!I104 -> 100 | J15: =+'02_Pricing'!J104 -> 100 | ... O15: =+'02_Pricing'!O104 -> 100 | P15: =+'06_Red_CAPEX'!Q88 -> 0

Sheet 02_Pricing
B3: Simulador 1 - Pricing & Elasticidad
B5: Categoria | C5: PVP Base | D5: Costo Unitario Base | E5: Vol PDV Base | F5: Ventas Base Mes 0 (ARS MM) | G5: Costo Base Mes 0 (ARS MM) | H5: Vol Base Mes 0 (Units) | I5: Margen % Base | J5: Elasticidad
B6: Medicamentos A | C6: 6617 | D6: 4800 | E6: 12600 | F6: =+C6*H6/1000000 -> 10004.904 | G6: =+D6*H6/1000000 -> 7257.6 | H6: =+E6*'00_General'!$C$9 -> 1512000 | I6: =+(F6-G6)/F6 -> 0.27459574 | J6: -0.3
B7: Nutricion | C7: 31266.154 | D7: 21260.985 | E7: 400 | F7: =+C7*H7/1000000 -> 1500.7754 | G7: =+D7*H7/1000000 -> 1020.5273 | H7: =+E7*'00_General'!$C$9 -> 48000 | I7: =+(F7-G7)/F7 -> 0.32 | J7: -1.1
B8: Parafarmacia | C8: 15159.347 | D8: 9853.5759 | E8: 1100 | F8: =+C8*H8/1000000 -> 2001.0339 | G8: =+D8*H8/1000000 -> 1300.672 | H8: =+E8*'00_General'!$C$9 -> 132000 | I8: =+(F8-G8)/F8 -> 0.35 | J8: -1
B9: Suplementos | C9: 20844.103 | D9: 12923.344 | E9: 700 | F9: =+C9*H9/1000000 -> 1750.9046 | G9: =+D9*H9/1000000 -> 1085.5609 | H9: =+E9*'00_General'!$C$9 -> 84000 | I9: =+(F9-G9)/F9 -> 0.38 | J9: -1.3
B10: Venta Libre | C10: 6948.0343 | D10: 4585.7026 | E10: 4500 | F10: =+C10*H10/1000000 -> 3751.9385 | G10: =+D10*H10/1000000 -> 2476.2794 | H10: =+E10*'00_General'!$C$9 -> 540000 | I10: =+(F10-G10)/F10 -> 0.34 | J10: -0.7
B11: Cuidado Bucal | C11: 4737.2961 | D11: 3268.7343 | E11: 2200 | F11: =+C11*H11/1000000 -> 1250.6462 | G11: =+D11*H11/1000000 -> 862.94586 | H11: =+E11*'00_General'!$C$9 -> 264000 | I11: =+(F11-G11)/F11 -> 0.31 | J11: -1.1
B12: Cuidado Piel | C12: 8527.133 | D12: 4945.7371 | E12: 2200 | F12: =+C12*H12/1000000 -> 2251.1631 | G12: =+D12*H12/1000000 -> 1305.6746 | H12: =+E12*'00_General'!$C$9 -> 264000 | I12: =+(F12-G12)/F12 -> 0.42 | J12: -1.2
B13: Bebe y Mama | C13: 12506.462 | D13: 8379.3293 | E13: 750 | F13: =+C13*H13/1000000 -> 1125.5816 | G13: =+D13*H13/1000000 -> 754.13964 | H13: =+E13*'00_General'!$C$9 -> 90000 | I13: =+(F13-G13)/F13 -> 0.33 | J13: -0.8
B14: Cuidado Cabello | C14: 3821.4188 | D14: 2445.7081 | E14: 3000 | F14: =+C14*H14/1000000 -> 1375.7108 | G14: =+D14*H14/1000000 -> 880.4549 | H14: =+E14*'00_General'!$C$9 -> 360000 | I14: =+(F14-G14)/F14 -> 0.36 | J14: -1.25
B15: Cuidado Personal | C15: 1908.2629 | D15: 1240.3709 | E15: 7100 | F15: =+C15*H15/1000000 -> 1625.84 | G15: =+D15*H15/1000000 -> 1056.796 | H15: =+E15*'00_General'!$C$9 -> 852000 | I15: =+(F15-G15)/F15 -> 0.35 | J15: -1.15
B16: Dermocosmetica | C16: 40014.722 | D16: 20807.655 | E16: 700 | F16: =+C16*H16/1000000 -> 3361.2366 | G16: =+D16*H16/1000000 -> 1747.8431 | H16: =+E16*'00_General'!$C$9 -> 84000 | I16: =+(F16-G16)/F16 -> 0.48 | J16: -1.4
B18: TOTAL | E18: =SUM(E6:E16) -> 35250 | F18: =SUM(F6:F16) -> 29999.735 | G18: =SUM(G6:G16) -> 19748.494 | H18: =SUM(H6:H16) -> 4230000 | I18: =+(F18-G18)/F18 -> 0.34171106
H19: =+F18*1000000/H18 -> 7092.1359
B21: Cambio PVP %
B23: Categoria | C23: Mes 0 | D23: Mes 1 | E23: Mes 2 | F23: Mes 3 | G23: Mes 4 | H23: Mes 5 | I23: Mes 6 | J23: Mes 7 | K23: Mes 8 | L23: Mes 9 | M23: Mes 10 | N23: Mes 11 | O23: Mes 12
B24: Medicamentos | D24: 0 | E24: 0 | F24: 0 | G24: 0 | H24: 0 | I24: 0 | J24: 0 | K24: 0 | L24: 0 | M24: 0 | N24: 0 | O24: 0
B25: Nutricion | D25: 0 | E25: 0 | F25: 0 | G25: 0 | H25: 0 | I25: 0 | J25: 0 | K25: 0 | L25: 0 | M25: 0 | N25: 0 | O25: 0
B26: Parafarmacia | D26: 0 | E26: 0 | F26: 0 | G26: 0 | H26: 0 | I26: 0 | J26: 0 | K26: 0 | L26: 0 | M26: 0 | N26: 0 | O26: 0
B27: Suplementos | D27: 0 | E27: 0 | F27: 0 | G27: 0 | H27: 0 | I27: 0 | J27: 0 | K27: 0 | L27: 0 | M27: 0 | N27: 0 | O27: 0
B28: Venta Libre | D28: 0 | E28: 0 | F28: 0 | G28: 0 | H28: 0 | I28: 0 | J28: 0 | K28: 0 | L28: 0 | M28: 0 | N28: 0 | O28: 0
B29: Cuidado Bucal | D29: 0 | E29: 0 | F29: 0 | G29: 0 | H29: 0 | I29: 0 | J29: 0 | K29: 0 | L29: 0 | M29: 0 | N29: 0 | O29: 0
B30: Cuidado Piel | D30: 0 | E30: 0 | F30: 0 | G30: 0 | H30: 0 | I30: 0 | J30: 0 | K30: 0 | L30: 0 | M30: 0 | N30: 0 | O30: 0
B31: Bebe y Mama | D31: 0 | E31: 0 | F31: 0 | G31: 0 | H31: 0 | I31: 0 | J31: 0 | K31: 0 | L31: 0 | M31: 0 | N31: 0 | O31: 0
B32: Cuidado Cabello | D32: 0 | E32: 0 | F32: 0 | G32: 0 | H32: 0 | I32: 0 | J32: 0 | K32: 0 | L32: 0 | M32: 0 | N32: 0 | O32: 0
B33: Cuidado Personal | D33: 0 | E33: 0 | F33: 0 | G33: 0 | H33: 0 | I33: 0 | J33: 0 | K33: 0 | L33: 0 | M33: 0 | N33: 0 | O33: 0
B34: Dermocosmetica | D34: 0 | E34: 0 | F34: 0 | G34: 0 | H34: 0 | I34: 0 | J34: 0 | K34: 0 | L34: 0 | M34: 0 | N34: 0 | O34: 0
B36: TOTAL / POND.
B38: Revenue Simulado
B40: Categoria | C40: Mes 0 | D40: Mes 1 | E40: Mes 2 | F40: Mes 3 | G40: Mes 4 | H40: Mes 5 | I40: Mes 6 | J40: Mes 7 | K40: Mes 8 | L40: Mes 9 | M40: Mes 10 | N40: Mes 11 | O40: Mes 12
B41: Medicamentos | C41: =+F6 -> 10004.904 | D41: =+(($H$6*(1+$J$6*$D$24))*($C$6*(1+$D$24)))/1000000 -> 10004.904 | E41: =+(($H6*(1+$J6*E24))*($C6*(1+E24)))/1000000 -> 10004.904 | F41: =+(($H6*(1+$J6*F24))*($C6*(1+F24)))/1000000 -> 10004.904 | G41: =+(($H6*(1+$J6*G24))*($C6*(1+G24)))/1000000 -> 10004.904 | H41: =+(($H6*(1+$J6*H24))*($C6*(1+H24)))/1000000 -> 10004.904 | I41: =+(($H6*(1+$J6*I24))*($C6*(1+I24)))/1000000 -> 10004.904 | J41: =+(($H6*(1+$J6*J24))*($C6*(1+J24)))/1000000 -> 10004.904 | K41: =+(($H6*(1+$J6*K24))*($C6*(1+K24)))/1000000 -> 10004.904 | L41: =+(($H6*(1+$J6*L24))*($C6*(1+L24)))/1000000 -> 10004.904 | ... O41: =+(($H6*(1+$J6*O24))*($C6*(1+O24)))/1000000 -> 10004.904
B42: Nutricion | C42: =+F7 -> 1500.7754 | D42: =+(($H7*(1+$J7*D25))*($C7*(1+D25)))/1000000 -> 1500.7754 | E42: =+(($H7*(1+$J7*E25))*($C7*(1+E25)))/1000000 -> 1500.7754 | F42: =+(($H7*(1+$J7*F25))*($C7*(1+F25)))/1000000 -> 1500.7754 | G42: =+(($H7*(1+$J7*G25))*($C7*(1+G25)))/1000000 -> 1500.7754 | H42: =+(($H7*(1+$J7*H25))*($C7*(1+H25)))/1000000 -> 1500.7754 | I42: =+(($H7*(1+$J7*I25))*($C7*(1+I25)))/1000000 -> 1500.7754 | J42: =+(($H7*(1+$J7*J25))*($C7*(1+J25)))/1000000 -> 1500.7754 | K42: =+(($H7*(1+$J7*K25))*($C7*(1+K25)))/1000000 -> 1500.7754 | ... O42: =+(($H7*(1+$J7*O25))*($C7*(1+O25)))/1000000 -> 1500.7754
B43: Parafarmacia | C43: =+F8 -> 2001.0339 | D43: =+(($H8*(1+$J8*D26))*($C8*(1+D26)))/1000000 -> 2001.0339 | E43: =+(($H8*(1+$J8*E26))*($C8*(1+E26)))/1000000 -> 2001.0339 | F43: =+(($H8*(1+$J8*F26))*($C8*(1+F26)))/1000000 -> 2001.0339 | G43: =+(($H8*(1+$J8*G26))*($C8*(1+G26)))/1000000 -> 2001.0339 | H43: =+(($H8*(1+$J8*H26))*($C8*(1+H26)))/1000000 -> 2001.0339 | I43: =+(($H8*(1+$J8*I26))*($C8*(1+I26)))/1000000 -> 2001.0339 | J43: =+(($H8*(1+$J8*J26))*($C8*(1+J26)))/1000000 -> 2001.0339 | K43: =+(($H8*(1+$J8*K26))*($C8*(1+K26)))/1000000 -> 2001.0339 | ... O43: =+(($H8*(1+$J8*O26))*($C8*(1+O26)))/1000000 -> 2001.0339
B44: Suplementos | C44: =+F9 -> 1750.9046 | D44: =+(($H9*(1+$J9*D27))*($C9*(1+D27)))/1000000 -> 1750.9046 | E44: =+(($H9*(1+$J9*E27))*($C9*(1+E27)))/1000000 -> 1750.9046 | F44: =+(($H9*(1+$J9*F27))*($C9*(1+F27)))/1000000 -> 1750.9046 | G44: =+(($H9*(1+$J9*G27))*($C9*(1+G27)))/1000000 -> 1750.9046 | H44: =+(($H9*(1+$J9*H27))*($C9*(1+H27)))/1000000 -> 1750.9046 | I44: =+(($H9*(1+$J9*I27))*($C9*(1+I27)))/1000000 -> 1750.9046 | J44: =+(($H9*(1+$J9*J27))*($C9*(1+J27)))/1000000 -> 1750.9046 | K44: =+(($H9*(1+$J9*K27))*($C9*(1+K27)))/1000000 -> 1750.9046 | ... O44: =+(($H9*(1+$J9*O27))*($C9*(1+O27)))/1000000 -> 1750.9046
B45: Venta Libre | C45: =+F10 -> 3751.9385 | D45: =+(($H10*(1+$J10*D28))*($C10*(1+D28)))/1000000 -> 3751.9385 | E45: =+(($H10*(1+$J10*E28))*($C10*(1+E28)))/1000000 -> 3751.9385 | F45: =+(($H10*(1+$J10*F28))*($C10*(1+F28)))/1000000 -> 3751.9385 | G45: =+(($H10*(1+$J10*G28))*($C10*(1+G28)))/1000000 -> 3751.9385 | H45: =+(($H10*(1+$J10*H28))*($C10*(1+H28)))/1000000 -> 3751.9385 | I45: =+(($H10*(1+$J10*I28))*($C10*(1+I28)))/1000000 -> 3751.9385 | J45: =+(($H10*(1+$J10*J28))*($C10*(1+J28)))/1000000 -> 3751.9385 | K45: =+(($H10*(1+$J10*K28))*($C10*(1+K28)))/1000000 -> 3751.9385 | ... O45: =+(($H10*(1+$J10*O28))*($C10*(1+O28)))/1000000 -> 3751.9385
B46: Cuidado Bucal | C46: =+F11 -> 1250.6462 | D46: =+(($H11*(1+$J11*D29))*($C11*(1+D29)))/1000000 -> 1250.6462 | E46: =+(($H11*(1+$J11*E29))*($C11*(1+E29)))/1000000 -> 1250.6462 | F46: =+(($H11*(1+$J11*F29))*($C11*(1+F29)))/1000000 -> 1250.6462 | G46: =+(($H11*(1+$J11*G29))*($C11*(1+G29)))/1000000 -> 1250.6462 | H46: =+(($H11*(1+$J11*H29))*($C11*(1+H29)))/1000000 -> 1250.6462 | I46: =+(($H11*(1+$J11*I29))*($C11*(1+I29)))/1000000 -> 1250.6462 | J46: =+(($H11*(1+$J11*J29))*($C11*(1+J29)))/1000000 -> 1250.6462 | K46: =+(($H11*(1+$J11*K29))*($C11*(1+K29)))/1000000 -> 1250.6462 | ... O46: =+(($H11*(1+$J11*O29))*($C11*(1+O29)))/1000000 -> 1250.6462
B47: Cuidado Piel | C47: =+F12 -> 2251.1631 | D47: =+(($H12*(1+$J12*D30))*($C12*(1+D30)))/1000000 -> 2251.1631 | E47: =+(($H12*(1+$J12*E30))*($C12*(1+E30)))/1000000 -> 2251.1631 | F47: =+(($H12*(1+$J12*F30))*($C12*(1+F30)))/1000000 -> 2251.1631 | G47: =+(($H12*(1+$J12*G30))*($C12*(1+G30)))/1000000 -> 2251.1631 | H47: =+(($H12*(1+$J12*H30))*($C12*(1+H30)))/1000000 -> 2251.1631 | I47: =+(($H12*(1+$J12*I30))*($C12*(1+I30)))/1000000 -> 2251.1631 | J47: =+(($H12*(1+$J12*J30))*($C12*(1+J30)))/1000000 -> 2251.1631 | K47: =+(($H12*(1+$J12*K30))*($C12*(1+K30)))/1000000 -> 2251.1631 | ... O47: =+(($H12*(1+$J12*O30))*($C12*(1+O30)))/1000000 -> 2251.1631
B48: Bebe y Mama | C48: =+F13 -> 1125.5816 | D48: =+(($H13*(1+$J13*D31))*($C13*(1+D31)))/1000000 -> 1125.5816 | E48: =+(($H13*(1+$J13*E31))*($C13*(1+E31)))/1000000 -> 1125.5816 | F48: =+(($H13*(1+$J13*F31))*($C13*(1+F31)))/1000000 -> 1125.5816 | G48: =+(($H13*(1+$J13*G31))*($C13*(1+G31)))/1000000 -> 1125.5816 | H48: =+(($H13*(1+$J13*H31))*($C13*(1+H31)))/1000000 -> 1125.5816 | I48: =+(($H13*(1+$J13*I31))*($C13*(1+I31)))/1000000 -> 1125.5816 | J48: =+(($H13*(1+$J13*J31))*($C13*(1+J31)))/1000000 -> 1125.5816 | K48: =+(($H13*(1+$J13*K31))*($C13*(1+K31)))/1000000 -> 1125.5816 | ... O48: =+(($H13*(1+$J13*O31))*($C13*(1+O31)))/1000000 -> 1125.5816
B49: Cuidado Cabello | C49: =+F14 -> 1375.7108 | D49: =+(($H14*(1+$J14*D32))*($C14*(1+D32)))/1000000 -> 1375.7108 | E49: =+(($H14*(1+$J14*E32))*($C14*(1+E32)))/1000000 -> 1375.7108 | F49: =+(($H14*(1+$J14*F32))*($C14*(1+F32)))/1000000 -> 1375.7108 | G49: =+(($H14*(1+$J14*G32))*($C14*(1+G32)))/1000000 -> 1375.7108 | H49: =+(($H14*(1+$J14*H32))*($C14*(1+H32)))/1000000 -> 1375.7108 | I49: =+(($H14*(1+$J14*I32))*($C14*(1+I32)))/1000000 -> 1375.7108 | J49: =+(($H14*(1+$J14*J32))*($C14*(1+J32)))/1000000 -> 1375.7108 | K49: =+(($H14*(1+$J14*K32))*($C14*(1+K32)))/1000000 -> 1375.7108 | ... O49: =+(($H14*(1+$J14*O32))*($C14*(1+O32)))/1000000 -> 1375.7108
...

Sheet 03_CatMan_DDI
B3: Simulador 2 - CatMan, Surtido, Cobertura y DDI
B5: Categoria | C5: SKUs Base | D5: Cobertura % | E5: Reduccion SKUs % | F5: Merma %
B6: Medicamentos | C6: 420 | D6: 0.95 | E6: 0.05 | F6: =MAX(0.002,0.012-E6*0.03) -> 0.0105
B7: Nutricion | C7: 160 | D7: 0.95 | E7: 0.05 | F7: =MAX(0.002,0.012-E7*0.03) -> 0.0105
B8: Parafarmacia | C8: 240 | D8: 0.95 | E8: 0.05 | F8: =MAX(0.002,0.012-E8*0.03) -> 0.0105
B9: Suplementos | C9: 180 | D9: 0.95 | E9: 0.05 | F9: =MAX(0.002,0.012-E9*0.03) -> 0.0105
B10: Venta Libre | C10: 260 | D10: 0.95 | E10: 0.05 | F10: =MAX(0.002,0.012-E10*0.03) -> 0.0105
B11: Cuidado Bucal | C11: 140 | D11: 0.95 | E11: 0.05 | F11: =MAX(0.002,0.012-E11*0.03) -> 0.0105
B12: Cuidado Piel | C12: 180 | D12: 0.95 | E12: 0.05 | F12: =MAX(0.002,0.012-E12*0.03) -> 0.0105
B13: Bebe y Mama | C13: 120 | D13: 0.95 | E13: 0.05 | F13: =MAX(0.002,0.012-E13*0.03) -> 0.0105
B14: Cuidado Cabello | C14: 160 | D14: 0.95 | E14: 0.05 | F14: =MAX(0.002,0.012-E14*0.03) -> 0.0105
B15: Cuidado Personal | C15: 190 | D15: 0.95 | E15: 0.05 | F15: =MAX(0.002,0.012-E15*0.03) -> 0.0105
B16: Dermocosmetica | C16: 220 | D16: 0.95 | E16: 0.05 | F16: =MAX(0.002,0.012-E16*0.03) -> 0.0105
B18: TOTAL / POND. | C18: =SUM(C6:C16) -> 2270 | D18: =AVERAGE(D6:D16) -> 0.95 | E18: =AVERAGE(E6:E16) -> 0.05 | F18: =SUMPRODUCT(F6:F16,P57:P67)/P69 -> 0.0105
B20: DDI Objetivo
B22: Categoria | C22: Mes 0 | D22: Mes 1 | E22: Mes 2 | F22: Mes 3 | G22: Mes 4 | H22: Mes 5 | I22: Mes 6 | J22: Mes 7 | K22: Mes 8 | L22: Mes 9 | M22: Mes 10 | N22: Mes 11 | O22: Mes 12
B23: Medicamentos | C23: 55 | D23: 47 | E23: 47 | F23: 47 | G23: 47 | H23: 47 | I23: 47 | J23: 47 | K23: 47 | L23: 47 | M23: 47 | N23: 47 | O23: 47
B24: Nutricion | C24: 65 | D24: 57 | E24: 57 | F24: 57 | G24: 57 | H24: 57 | I24: 57 | J24: 57 | K24: 57 | L24: 57 | M24: 57 | N24: 57 | O24: 57
B25: Parafarmacia | C25: 70 | D25: 62 | E25: 62 | F25: 62 | G25: 62 | H25: 62 | I25: 62 | J25: 62 | K25: 62 | L25: 62 | M25: 62 | N25: 62 | O25: 62
B26: Suplementos | C26: 75 | D26: 67 | E26: 67 | F26: 67 | G26: 67 | H26: 67 | I26: 67 | J26: 67 | K26: 67 | L26: 67 | M26: 67 | N26: 67 | O26: 67
B27: Venta Libre | C27: 60 | D27: 52 | E27: 52 | F27: 52 | G27: 52 | H27: 52 | I27: 52 | J27: 52 | K27: 52 | L27: 52 | M27: 52 | N27: 52 | O27: 52
B28: Cuidado Bucal | C28: 58 | D28: 50 | E28: 50 | F28: 50 | G28: 50 | H28: 50 | I28: 50 | J28: 50 | K28: 50 | L28: 50 | M28: 50 | N28: 50 | O28: 50
B29: Cuidado Piel | C29: 70 | D29: 62 | E29: 62 | F29: 62 | G29: 62 | H29: 62 | I29: 62 | J29: 62 | K29: 62 | L29: 62 | M29: 62 | N29: 62 | O29: 62
B30: Bebe y Mama | C30: 62 | D30: 54 | E30: 54 | F30: 54 | G30: 54 | H30: 54 | I30: 54 | J30: 54 | K30: 54 | L30: 54 | M30: 54 | N30: 54 | O30: 54
B31: Cuidado Cabello | C31: 65 | D31: 57 | E31: 57 | F31: 57 | G31: 57 | H31: 57 | I31: 57 | J31: 57 | K31: 57 | L31: 57 | M31: 57 | N31: 57 | O31: 57
B32: Cuidado Personal | C32: 66 | D32: 58 | E32: 58 | F32: 58 | G32: 58 | H32: 58 | I32: 58 | J32: 58 | K32: 58 | L32: 58 | M32: 58 | N32: 58 | O32: 58
B33: Dermocosmetica | C33: 80 | D33: 72 | E33: 72 | F33: 72 | G33: 72 | H33: 72 | I33: 72 | J33: 72 | K33: 72 | L33: 72 | M33: 72 | N33: 72 | O33: 72
B35: TOTAL / POND. | C35: =SUMPRODUCT(C23:C33,C74:C84)/C86 -> 63.927442 | D35: =SUMPRODUCT(D23:D33,D74:D84)/D86 -> 56.081875 | E35: =SUMPRODUCT(E23:E33,E74:E84)/E86 -> 56.081875 | F35: =SUMPRODUCT(F23:F33,F74:F84)/F86 -> 56.081875 | G35: =SUMPRODUCT(G23:G33,G74:G84)/G86 -> 56.081875 | H35: =SUMPRODUCT(H23:H33,H74:H84)/H86 -> 56.081875 | I35: =SUMPRODUCT(I23:I33,I74:I84)/I86 -> 56.081875 | J35: =SUMPRODUCT(J23:J33,J74:J84)/J86 -> 56.081875 | ... O35: =SUMPRODUCT(O23:O33,O74:O84)/O86 -> 56.081875
B37: Quiebre Estimado %
B39: Categoria | C39: Mes 0 | D39: Mes 1 | E39: Mes 2 | F39: Mes 3 | G39: Mes 4 | H39: Mes 5 | I39: Mes 6 | J39: Mes 7 | K39: Mes 8 | L39: Mes 9 | M39: Mes 10 | N39: Mes 11 | O39: Mes 12
B40: Medicamentos | D40: =MAX(0,(1-$D6)*0.12+MAX(0,45-D23)*0.004) -> 0.006 | E40: =MAX(0,(1-$D6)*0.12+MAX(0,45-E23)*0.004) -> 0.006 | F40: =MAX(0,(1-$D6)*0.12+MAX(0,45-F23)*0.004) -> 0.006 | G40: =MAX(0,(1-$D6)*0.12+MAX(0,45-G23)*0.004) -> 0.006 | H40: =MAX(0,(1-$D6)*0.12+MAX(0,45-H23)*0.004) -> 0.006 | I40: =MAX(0,(1-$D6)*0.12+MAX(0,45-I23)*0.004) -> 0.006 | J40: =MAX(0,(1-$D6)*0.12+MAX(0,45-J23)*0.004) -> 0.006 | K40: =MAX(0,(1-$D6)*0.12+MAX(0,45-K23)*0.004) -> 0.006 | ... O40: =MAX(0,(1-$D6)*0.12+MAX(0,45-O23)*0.004) -> 0.006
B41: Nutricion | D41: =MAX(0,(1-$D7)*0.12+MAX(0,45-D24)*0.004) -> 0.006 | E41: =MAX(0,(1-$D7)*0.12+MAX(0,45-E24)*0.004) -> 0.006 | F41: =MAX(0,(1-$D7)*0.12+MAX(0,45-F24)*0.004) -> 0.006 | G41: =MAX(0,(1-$D7)*0.12+MAX(0,45-G24)*0.004) -> 0.006 | H41: =MAX(0,(1-$D7)*0.12+MAX(0,45-H24)*0.004) -> 0.006 | I41: =MAX(0,(1-$D7)*0.12+MAX(0,45-I24)*0.004) -> 0.006 | J41: =MAX(0,(1-$D7)*0.12+MAX(0,45-J24)*0.004) -> 0.006 | K41: =MAX(0,(1-$D7)*0.12+MAX(0,45-K24)*0.004) -> 0.006 | ... O41: =MAX(0,(1-$D7)*0.12+MAX(0,45-O24)*0.004) -> 0.006
B42: Parafarmacia | D42: =MAX(0,(1-$D8)*0.12+MAX(0,45-D25)*0.004) -> 0.006 | E42: =MAX(0,(1-$D8)*0.12+MAX(0,45-E25)*0.004) -> 0.006 | F42: =MAX(0,(1-$D8)*0.12+MAX(0,45-F25)*0.004) -> 0.006 | G42: =MAX(0,(1-$D8)*0.12+MAX(0,45-G25)*0.004) -> 0.006 | H42: =MAX(0,(1-$D8)*0.12+MAX(0,45-H25)*0.004) -> 0.006 | I42: =MAX(0,(1-$D8)*0.12+MAX(0,45-I25)*0.004) -> 0.006 | J42: =MAX(0,(1-$D8)*0.12+MAX(0,45-J25)*0.004) -> 0.006 | K42: =MAX(0,(1-$D8)*0.12+MAX(0,45-K25)*0.004) -> 0.006 | ... O42: =MAX(0,(1-$D8)*0.12+MAX(0,45-O25)*0.004) -> 0.006
B43: Suplementos | D43: =MAX(0,(1-$D9)*0.12+MAX(0,45-D26)*0.004) -> 0.006 | E43: =MAX(0,(1-$D9)*0.12+MAX(0,45-E26)*0.004) -> 0.006 | F43: =MAX(0,(1-$D9)*0.12+MAX(0,45-F26)*0.004) -> 0.006 | G43: =MAX(0,(1-$D9)*0.12+MAX(0,45-G26)*0.004) -> 0.006 | H43: =MAX(0,(1-$D9)*0.12+MAX(0,45-H26)*0.004) -> 0.006 | I43: =MAX(0,(1-$D9)*0.12+MAX(0,45-I26)*0.004) -> 0.006 | J43: =MAX(0,(1-$D9)*0.12+MAX(0,45-J26)*0.004) -> 0.006 | K43: =MAX(0,(1-$D9)*0.12+MAX(0,45-K26)*0.004) -> 0.006 | ... O43: =MAX(0,(1-$D9)*0.12+MAX(0,45-O26)*0.004) -> 0.006
B44: Venta Libre | D44: =MAX(0,(1-$D10)*0.12+MAX(0,45-D27)*0.004) -> 0.006 | E44: =MAX(0,(1-$D10)*0.12+MAX(0,45-E27)*0.004) -> 0.006 | F44: =MAX(0,(1-$D10)*0.12+MAX(0,45-F27)*0.004) -> 0.006 | G44: =MAX(0,(1-$D10)*0.12+MAX(0,45-G27)*0.004) -> 0.006 | H44: =MAX(0,(1-$D10)*0.12+MAX(0,45-H27)*0.004) -> 0.006 | I44: =MAX(0,(1-$D10)*0.12+MAX(0,45-I27)*0.004) -> 0.006 | J44: =MAX(0,(1-$D10)*0.12+MAX(0,45-J27)*0.004) -> 0.006 | K44: =MAX(0,(1-$D10)*0.12+MAX(0,45-K27)*0.004) -> 0.006 | ... O44: =MAX(0,(1-$D10)*0.12+MAX(0,45-O27)*0.004) -> 0.006
B45: Cuidado Bucal | D45: =MAX(0,(1-$D11)*0.12+MAX(0,45-D28)*0.004) -> 0.006 | E45: =MAX(0,(1-$D11)*0.12+MAX(0,45-E28)*0.004) -> 0.006 | F45: =MAX(0,(1-$D11)*0.12+MAX(0,45-F28)*0.004) -> 0.006 | G45: =MAX(0,(1-$D11)*0.12+MAX(0,45-G28)*0.004) -> 0.006 | H45: =MAX(0,(1-$D11)*0.12+MAX(0,45-H28)*0.004) -> 0.006 | I45: =MAX(0,(1-$D11)*0.12+MAX(0,45-I28)*0.004) -> 0.006 | J45: =MAX(0,(1-$D11)*0.12+MAX(0,45-J28)*0.004) -> 0.006 | K45: =MAX(0,(1-$D11)*0.12+MAX(0,45-K28)*0.004) -> 0.006 | ... O45: =MAX(0,(1-$D11)*0.12+MAX(0,45-O28)*0.004) -> 0.006
B46: Cuidado Piel | D46: =MAX(0,(1-$D12)*0.12+MAX(0,45-D29)*0.004) -> 0.006 | E46: =MAX(0,(1-$D12)*0.12+MAX(0,45-E29)*0.004) -> 0.006 | F46: =MAX(0,(1-$D12)*0.12+MAX(0,45-F29)*0.004) -> 0.006 | G46: =MAX(0,(1-$D12)*0.12+MAX(0,45-G29)*0.004) -> 0.006 | H46: =MAX(0,(1-$D12)*0.12+MAX(0,45-H29)*0.004) -> 0.006 | I46: =MAX(0,(1-$D12)*0.12+MAX(0,45-I29)*0.004) -> 0.006 | J46: =MAX(0,(1-$D12)*0.12+MAX(0,45-J29)*0.004) -> 0.006 | K46: =MAX(0,(1-$D12)*0.12+MAX(0,45-K29)*0.004) -> 0.006 | ... O46: =MAX(0,(1-$D12)*0.12+MAX(0,45-O29)*0.004) -> 0.006
B47: Bebe y Mama | D47: =MAX(0,(1-$D13)*0.12+MAX(0,45-D30)*0.004) -> 0.006 | E47: =MAX(0,(1-$D13)*0.12+MAX(0,45-E30)*0.004) -> 0.006 | F47: =MAX(0,(1-$D13)*0.12+MAX(0,45-F30)*0.004) -> 0.006 | G47: =MAX(0,(1-$D13)*0.12+MAX(0,45-G30)*0.004) -> 0.006 | H47: =MAX(0,(1-$D13)*0.12+MAX(0,45-H30)*0.004) -> 0.006 | I47: =MAX(0,(1-$D13)*0.12+MAX(0,45-I30)*0.004) -> 0.006 | J47: =MAX(0,(1-$D13)*0.12+MAX(0,45-J30)*0.004) -> 0.006 | K47: =MAX(0,(1-$D13)*0.12+MAX(0,45-K30)*0.004) -> 0.006 | ... O47: =MAX(0,(1-$D13)*0.12+MAX(0,45-O30)*0.004) -> 0.006
B48: Cuidado Cabello | D48: =MAX(0,(1-$D14)*0.12+MAX(0,45-D31)*0.004) -> 0.006 | E48: =MAX(0,(1-$D14)*0.12+MAX(0,45-E31)*0.004) -> 0.006 | F48: =MAX(0,(1-$D14)*0.12+MAX(0,45-F31)*0.004) -> 0.006 | G48: =MAX(0,(1-$D14)*0.12+MAX(0,45-G31)*0.004) -> 0.006 | H48: =MAX(0,(1-$D14)*0.12+MAX(0,45-H31)*0.004) -> 0.006 | I48: =MAX(0,(1-$D14)*0.12+MAX(0,45-I31)*0.004) -> 0.006 | J48: =MAX(0,(1-$D14)*0.12+MAX(0,45-J31)*0.004) -> 0.006 | K48: =MAX(0,(1-$D14)*0.12+MAX(0,45-K31)*0.004) -> 0.006 | ... O48: =MAX(0,(1-$D14)*0.12+MAX(0,45-O31)*0.004) -> 0.006
B49: Cuidado Personal | D49: =MAX(0,(1-$D15)*0.12+MAX(0,45-D32)*0.004) -> 0.006 | E49: =MAX(0,(1-$D15)*0.12+MAX(0,45-E32)*0.004) -> 0.006 | F49: =MAX(0,(1-$D15)*0.12+MAX(0,45-F32)*0.004) -> 0.006 | G49: =MAX(0,(1-$D15)*0.12+MAX(0,45-G32)*0.004) -> 0.006 | H49: =MAX(0,(1-$D15)*0.12+MAX(0,45-H32)*0.004) -> 0.006 | I49: =MAX(0,(1-$D15)*0.12+MAX(0,45-I32)*0.004) -> 0.006 | J49: =MAX(0,(1-$D15)*0.12+MAX(0,45-J32)*0.004) -> 0.006 | K49: =MAX(0,(1-$D15)*0.12+MAX(0,45-K32)*0.004) -> 0.006 | ... O49: =MAX(0,(1-$D15)*0.12+MAX(0,45-O32)*0.004) -> 0.006
...

Sheet 04_Digital_Logistica
B3: Simulador 3 - Digital, Fulfillment y Cost-to-Serve
B5: Mix % Canal / Modelo | C5: Mes 0 | D5: Mes 1 | E5: Mes 2 | F5: Mes 3 | G5: Mes 4 | H5: Mes 5 | I5: Mes 6 | J5: Mes 7 | K5: Mes 8 | L5: Mes 9 | M5: Mes 10 | N5: Mes 11 | O5: Mes 12 | P5: Costo-to-Serve % | Q5: SLA Prometido | R5: Penalidad SLA | S5: Costo Logistico (ARS MM) | T5: Score Servicio
B7: Tienda Fisica | C7: =100%-C8-C9-C10 -> 0.84356451 | D7: =100%-D8-D9-D10 -> 0.83280023 | E7: =100%-E8-E9-E10 -> 0.83227555 | F7: =100%-F8-F9-F10 -> 0.83250594 | G7: =100%-G8-G9-G10 -> 0.8317604 | H7: =100%-H8-H9-H10 -> 0.83103388 | I7: =100%-I8-I9-I10 -> 0.81244533 | J7: =100%-J8-J9-J10 -> 0.81284635 | ... O7: =100%-O8-O9-O10 -> 0.76214625 | P7: 0.025 | Q7: Inmediato | R7: 0 | S7: ='01_Master_Variables'!C6*C7*(P7+R7) -> 632.3465 | T7: =MAX(0,100-(P7+R7)*300) -> 92.5
B8: Delivery | C8: 0.05 | D8: 0.05 | E8: 0.05 | F8: 0.05 | G8: 0.05 | H8: 0.05 | I8: 0.05 | J8: 0.05 | K8: 0.05 | L8: 0.05 | M8: 0.05 | N8: 0.05 | O8: 0.05 | P8: 0.12 | Q8: 24/48 hs | R8: 0 | S8: ='01_Master_Variables'!C6*C8*(P8+R8) -> 179.907 | T8: =MAX(0,100-(P8+R8)*300) -> 64
B9: Pick-up | C9: 0.07 | D9: 0.08 | E9: 0.08 | F9: 0.08 | G9: 0.08 | H9: 0.08 | I9: 0.08 | J9: 0.08 | K9: 0.08 | L9: 0.08 | M9: 0.08 | N9: 0.08 | O9: 0.08 | P9: 0.055 | Q9: 4 hs | R9: 0 | S9: ='01_Master_Variables'!C6*C9*(P9+R9) -> 115.44033 | T9: =MAX(0,100-(P9+R9)*300) -> 83.5
B10: Hub/Dark Store | C10: =+('07_PL_TiposPDV'!D25+'07_PL_TiposPDV'!D26)/'01_Master_Variables'!C6 -> 0.036435492 | D10: =+('07_PL_TiposPDV'!E25+'07_PL_TiposPDV'!E26)/'01_Master_Variables'!D6 -> 0.037199767 | E10: =+('07_PL_TiposPDV'!F25+'07_PL_TiposPDV'!F26)/'01_Master_Variables'!E6 -> 0.037724449 | F10: =+('07_PL_TiposPDV'!G25+'07_PL_TiposPDV'!G26)/'01_Master_Variables'!F6 -> 0.037494059 | G10: =+('07_PL_TiposPDV'!H25+'07_PL_TiposPDV'!H26)/'01_Master_Variables'!G6 -> 0.038239604 | H10: =+('07_PL_TiposPDV'!I25+'07_PL_TiposPDV'!I26)/'01_Master_Variables'!H6 -> 0.03896612 | I10: =+('07_PL_TiposPDV'!J25+'07_PL_TiposPDV'!J26)/'01_Master_Variables'!I6 -> 0.057554672 | J10: =+('07_PL_TiposPDV'!K25+'07_PL_TiposPDV'!K26)/'01_Master_Variables'!J6 -> 0.057153652 | ... O10: =+('07_PL_TiposPDV'!P25+'07_PL_TiposPDV'!P26)/'01_Master_Variables'!O6 -> 0.10785375 | P10: 0.085 | Q10: Same day | R10: 0.01 | S10: ='01_Master_Variables'!C6*C10*(P10+R10) -> 103.7875 | T10: =MAX(0,100-(P10+R10)*300) -> 71.5
B12: TOTAL / CONTROL | C12: =SUM(C7:C10) -> 1 | D12: =SUM(D7:D10) -> 1 | E12: =SUM(E7:E10) -> 1 | F12: =SUM(F7:F10) -> 1 | G12: =SUM(G7:G10) -> 1 | H12: =SUM(H7:H10) -> 1 | I12: =SUM(I7:I10) -> 1 | J12: =SUM(J7:J10) -> 1 | ... O12: =SUM(O7:O10) -> 1 | P12: =SUMPRODUCT(C7:C10,P7:P10) -> 0.03403613 | S12: =SUM(S7:S10) -> 1031.4813 | T12: =SUMPRODUCT(T7:T10,#REF!) -> #REF!
P13: =+(C7*P7+P9*C9)/(C7+C9) -> 0.027298688
B15: Costo Logistico (ARS MM) | C15: Mes 0 | D15: Mes 1 | E15: Mes 2 | F15: Mes 3 | G15: Mes 4 | H15: Mes 5 | I15: Mes 6 | J15: Mes 7 | K15: Mes 8 | L15: Mes 9 | M15: Mes 10 | N15: Mes 11 | O15: Mes 12 | P15: Total
B16: Tienda Fisica | C16: =+'01_Master_Variables'!C$6*'04_Digital_Logistica'!C7*('04_Digital_Logistica'!$P7+'04_Digital_Logistica'!$R7) -> 632.3465 | D16: =+'01_Master_Variables'!D$6*'04_Digital_Logistica'!D7*('04_Digital_Logistica'!$P7+'04_Digital_Logistica'!$R7) -> 611.45159 | E16: =+'01_Master_Variables'!E$6*'04_Digital_Logistica'!E7*('04_Digital_Logistica'!$P7+'04_Digital_Logistica'!$R7) -> 602.56747 | F16: =+'01_Master_Variables'!F$6*'04_Digital_Logistica'!F7*('04_Digital_Logistica'!$P7+'04_Digital_Logistica'!$R7) -> 606.4379 | G16: =+'01_Master_Variables'!G$6*'04_Digital_Logistica'!G7*('04_Digital_Logistica'!$P7+'04_Digital_Logistica'!$R7) -> 594.08187 | H16: =+'01_Master_Variables'!H$6*'04_Digital_Logistica'!H7*('04_Digital_Logistica'!$P7+'04_Digital_Logistica'!$R7) -> 582.4961 | I16: =+'01_Master_Variables'!I$6*'04_Digital_Logistica'!I7*('04_Digital_Logistica'!$P7+'04_Digital_Logistica'!$R7) -> 569.93601 | J16: =+'01_Master_Variables'!J$6*'04_Digital_Logistica'!J7*('04_Digital_Logistica'!$P7+'04_Digital_Logistica'!$R7) -> 574.21828 | ... O16: =+'01_Master_Variables'!O$6*'04_Digital_Logistica'!O7*('04_Digital_Logistica'!$P7+'04_Digital_Logistica'!$R7) -> 562.22674 | P16: =SUM(D16:O16) -> 6960.4579
B17: Delivery | C17: =+'01_Master_Variables'!C$6*'04_Digital_Logistica'!C8*('04_Digital_Logistica'!$P8+'04_Digital_Logistica'!$R8) -> 179.907 | D17: =+'01_Master_Variables'!D$6*'04_Digital_Logistica'!D8*('04_Digital_Logistica'!$P8+'04_Digital_Logistica'!$R8) -> 176.21078 | E17: =+'01_Master_Variables'!E$6*'04_Digital_Logistica'!E8*('04_Digital_Logistica'!$P8+'04_Digital_Logistica'!$R8) -> 173.75999 | F17: =+'01_Master_Variables'!F$6*'04_Digital_Logistica'!F8*('04_Digital_Logistica'!$P8+'04_Digital_Logistica'!$R8) -> 174.8277 | G17: =+'01_Master_Variables'!G$6*'04_Digital_Logistica'!G8*('04_Digital_Logistica'!$P8+'04_Digital_Logistica'!$R8) -> 171.41914 | H17: =+'01_Master_Variables'!H$6*'04_Digital_Logistica'!H8*('04_Digital_Logistica'!$P8+'04_Digital_Logistica'!$R8) -> 168.22306 | I17: =+'01_Master_Variables'!I$6*'04_Digital_Logistica'!I8*('04_Digital_Logistica'!$P8+'04_Digital_Logistica'!$R8) -> 168.36166 | J17: =+'01_Master_Variables'!J$6*'04_Digital_Logistica'!J8*('04_Digital_Logistica'!$P8+'04_Digital_Logistica'!$R8) -> 169.54297 | ... O17: =+'01_Master_Variables'!O$6*'04_Digital_Logistica'!O8*('04_Digital_Logistica'!$P8+'04_Digital_Logistica'!$R8) -> 177.04531 | P17: =SUM(D17:O17) -> 2068.1953
B18: Pick-up | C18: =+'01_Master_Variables'!C$6*'04_Digital_Logistica'!C9*('04_Digital_Logistica'!$P9+'04_Digital_Logistica'!$R9) -> 115.44033 | D18: =+'01_Master_Variables'!D$6*'04_Digital_Logistica'!D9*('04_Digital_Logistica'!$P9+'04_Digital_Logistica'!$R9) -> 129.22124 | E18: =+'01_Master_Variables'!E$6*'04_Digital_Logistica'!E9*('04_Digital_Logistica'!$P9+'04_Digital_Logistica'!$R9) -> 127.42399 | F18: =+'01_Master_Variables'!F$6*'04_Digital_Logistica'!F9*('04_Digital_Logistica'!$P9+'04_Digital_Logistica'!$R9) -> 128.20698 | G18: =+'01_Master_Variables'!G$6*'04_Digital_Logistica'!G9*('04_Digital_Logistica'!$P9+'04_Digital_Logistica'!$R9) -> 125.70737 | H18: =+'01_Master_Variables'!H$6*'04_Digital_Logistica'!H9*('04_Digital_Logistica'!$P9+'04_Digital_Logistica'!$R9) -> 123.36358 | I18: =+'01_Master_Variables'!I$6*'04_Digital_Logistica'!I9*('04_Digital_Logistica'!$P9+'04_Digital_Logistica'!$R9) -> 123.46522 | J18: =+'01_Master_Variables'!J$6*'04_Digital_Logistica'!J9*('04_Digital_Logistica'!$P9+'04_Digital_Logistica'!$R9) -> 124.33151 | ... O18: =+'01_Master_Variables'!O$6*'04_Digital_Logistica'!O9*('04_Digital_Logistica'!$P9+'04_Digital_Logistica'!$R9) -> 129.83323 | P18: =SUM(D18:O18) -> 1516.6765
B19: Hub/Dark Store | C19: =+'01_Master_Variables'!C$6*'04_Digital_Logistica'!C10*('04_Digital_Logistica'!$P10+'04_Digital_Logistica'!$R10) -> 103.7875 | D19: =+'01_Master_Variables'!D$6*'04_Digital_Logistica'!D10*('04_Digital_Logistica'!$P10+'04_Digital_Logistica'!$R10) -> 103.7875 | E19: =+'01_Master_Variables'!E$6*'04_Digital_Logistica'!E10*('04_Digital_Logistica'!$P10+'04_Digital_Logistica'!$R10) -> 103.7875 | F19: =+'01_Master_Variables'!F$6*'04_Digital_Logistica'!F10*('04_Digital_Logistica'!$P10+'04_Digital_Logistica'!$R10) -> 103.7875 | G19: =+'01_Master_Variables'!G$6*'04_Digital_Logistica'!G10*('04_Digital_Logistica'!$P10+'04_Digital_Logistica'!$R10) -> 103.7875 | H19: =+'01_Master_Variables'!H$6*'04_Digital_Logistica'!H10*('04_Digital_Logistica'!$P10+'04_Digital_Logistica'!$R10) -> 103.7875 | I19: =+'01_Master_Variables'!I$6*'04_Digital_Logistica'!I10*('04_Digital_Logistica'!$P10+'04_Digital_Logistica'!$R10) -> 153.425 | J19: =+'01_Master_Variables'!J$6*'04_Digital_Logistica'!J10*('04_Digital_Logistica'!$P10+'04_Digital_Logistica'!$R10) -> 153.425 | ... O19: =+'01_Master_Variables'!O$6*'04_Digital_Logistica'!O10*('04_Digital_Logistica'!$P10+'04_Digital_Logistica'!$R10) -> 302.3375 | P19: =SUM(D19:O19) -> 2039.65
C20: =SUM(C16:C19) -> 1031.4813 | D20: =SUM(D16:D19) -> 1020.6711 | E20: =SUM(E16:E19) -> 1007.539 | F20: =SUM(F16:F19) -> 1013.2601 | G20: =SUM(G16:G19) -> 994.99588 | H20: =SUM(H16:H19) -> 977.87025 | I20: =SUM(I16:I19) -> 1015.1879 | J20: =SUM(J16:J19) -> 1021.5178 | ... O20: =SUM(O16:O19) -> 1171.4428 | P20: =SUM(D20:O20) -> 12584.98
B26: Criterios Digital
B27: Delivery es un % target configurable; no debe asumirse gratis.
B28: Apertura/cierre de PDV modifica venta y costo logístico por zona.
B29: Hubs/Dark Store priorizan Éticos y eficiencia de última milla.

Sheet 05_CLV_Marketing
B2: Simulador 4 - CLV, Segmentacion y Marketing
B4: Segmento | C4: # Clientes Base | D4: Ticket Promedio | E4: Frecuencia Mensual | F4: Consumo Mensual | G4: Churn Base %
B5: VIPs | C5: 552631.58 | D5: =7092*2.5 -> 17730 | E5: 1.8 | F5: =+E5*D5 -> 31914 | G5: 0.015
B6: Riesgo Fuga | C6: 1105263.2 | D6: =7092*1.26 -> 8935.92 | E6: 0.9 | F6: =+E6*D6 -> 8042.328 | G6: 0.06
B7: Oportunistas | C7: 1842105.3 | D7: =7092*0.6 -> 4255.2 | E7: 0.45 | F7: =+E7*D7 -> 1914.84 | G7: 0.08
B8: TOTAL | C8: =SUM(C5:C7) -> 3500000 | D8: =SUMPRODUCT(D5:D7,$C$5:$C$7)/$C$8 -> 7860.9221 | E8: =SUMPRODUCT(E5:E7,$C$5:$C$7)/$C$8 -> 0.80526316 | F8: =SUMPRODUCT(F5:F7,$C$5:$C$7)/$C$8 -> 8586.5457 | G8: =SUMPRODUCT(G5:G7,C5:C7)/SUM(C5:C7) -> 0.063421053
B10: Churn Base % | C10: Mes 0 | D10: Mes 1 | E10: Mes 2 | F10: Mes 3 | G10: Mes 4 | H10: Mes 5 | I10: Mes 6 | J10: Mes 7 | K10: Mes 8 | L10: Mes 9 | M10: Mes 10 | N10: Mes 11 | O10: Mes 12
B11: VIPs | C11: 0.015 | D11: 0.015 | E11: 0.015 | F11: 0.015 | G11: 0.015 | H11: 0.015 | I11: 0.015 | J11: 0.015 | K11: 0.015 | L11: 0.015 | M11: 0.015 | N11: 0.015 | O11: 0.015
B12: Riesgo Fuga | C12: 0.06 | D12: 0.06 | E12: 0.06 | F12: 0.06 | G12: 0.06 | H12: 0.06 | I12: 0.06 | J12: 0.06 | K12: 0.06 | L12: 0.06 | M12: 0.06 | N12: 0.06 | O12: 0.06
B13: Oportunistas | C13: 0.08 | D13: 0.08 | E13: 0.08 | F13: 0.08 | G13: 0.08 | H13: 0.08 | I13: 0.08 | J13: 0.08 | K13: 0.08 | L13: 0.08 | M13: 0.08 | N13: 0.08 | O13: 0.08
B14: Nuevos
C15: =SUMPRODUCT(C11:C14,$C$39:$C$42)/$C$43 -> 0.063421053 | D15: =SUMPRODUCT(D11:D14,$C$39:$C$42)/$C$43 -> 0.063421053 | E15: =SUMPRODUCT(E11:E14,$C$39:$C$42)/$C$43 -> 0.063421053 | F15: =SUMPRODUCT(F11:F14,$C$39:$C$42)/$C$43 -> 0.063421053 | G15: =SUMPRODUCT(G11:G14,$C$39:$C$42)/$C$43 -> 0.063421053 | H15: =SUMPRODUCT(H11:H14,$C$39:$C$42)/$C$43 -> 0.063421053 | I15: =SUMPRODUCT(I11:I14,$C$39:$C$42)/$C$43 -> 0.063421053 | J15: =SUMPRODUCT(J11:J14,$C$39:$C$42)/$C$43 -> 0.063421053 | ... O15: =SUMPRODUCT(O11:O14,$C$39:$C$42)/$C$43 -> 0.063421053
B17: Foco Retención % | C17: Mes 0 | D17: Mes 1 | E17: Mes 2 | F17: Mes 3 | G17: Mes 4 | H17: Mes 5 | I17: Mes 6 | J17: Mes 7 | K17: Mes 8 | L17: Mes 9 | M17: Mes 10 | N17: Mes 11 | O17: Mes 12
B18: VIPs | D18: 0.5 | E18: 0.5 | F18: 0.5 | G18: 0.5 | H18: 0.5 | I18: 0.5 | J18: 0.5 | K18: 0.5 | L18: 0.5 | M18: 0.5 | N18: 0.5 | O18: 0.5
B19: Riesgo Fuga | D19: 0.5 | E19: 0.5 | F19: 0.5 | G19: 0.5 | H19: 0.5 | I19: 0.5 | J19: 0.5 | K19: 0.5 | L19: 0.5 | M19: 0.5 | N19: 0.5 | O19: 0.5
B20: Oportunistas | D20: 0 | E20: 0 | F20: 0 | G20: 0 | H20: 0 | I20: 0 | J20: 0 | K20: 0 | L20: 0 | M20: 0 | N20: 0 | O20: 0
B21: Nuevos
C22: =SUM(C18:C21) -> 0 | D22: =SUM(D18:D21) -> 1 | E22: =SUM(E18:E21) -> 1 | F22: =SUM(F18:F21) -> 1 | G22: =SUM(G18:G21) -> 1 | H22: =SUM(H18:H21) -> 1 | I22: =SUM(I18:I21) -> 1 | J22: =SUM(J18:J21) -> 1 | ... O22: =SUM(O18:O21) -> 1
B24: Churn Ajustado % | C24: Mes 0 | D24: Mes 1 | E24: Mes 2 | F24: Mes 3 | G24: Mes 4 | H24: Mes 5 | I24: Mes 6 | J24: Mes 7 | K24: Mes 8 | L24: Mes 9 | M24: Mes 10 | N24: Mes 11 | O24: Mes 12
B25: VIPs | D25: =MAX(0,+D11*(1-D18*0.5)) -> 0.01125 | E25: =MAX(0,+E11*(1-E18*0.5)) -> 0.01125 | F25: =MAX(0,+F11*(1-F18*0.5)) -> 0.01125 | G25: =MAX(0,+G11*(1-G18*0.5)) -> 0.01125 | H25: =MAX(0,+H11*(1-H18*0.5)) -> 0.01125 | I25: =MAX(0,+I11*(1-I18*0.5)) -> 0.01125 | J25: =MAX(0,+J11*(1-J18*0.5)) -> 0.01125 | K25: =MAX(0,+K11*(1-K18*0.5)) -> 0.01125 | ... O25: =MAX(0,+O11*(1-O18*0.5)) -> 0.01125
B26: Riesgo Fuga | D26: =MAX(0,+D12*(1-D19*0.5)) -> 0.045 | E26: =MAX(0,+E12*(1-E19*0.5)) -> 0.045 | F26: =MAX(0,+F12*(1-F19*0.5)) -> 0.045 | G26: =MAX(0,+G12*(1-G19*0.5)) -> 0.045 | H26: =MAX(0,+H12*(1-H19*0.5)) -> 0.045 | I26: =MAX(0,+I12*(1-I19*0.5)) -> 0.045 | J26: =MAX(0,+J12*(1-J19*0.5)) -> 0.045 | K26: =MAX(0,+K12*(1-K19*0.5)) -> 0.045 | ... O26: =MAX(0,+O12*(1-O19*0.5)) -> 0.045
B27: Oportunistas | D27: =MAX(0,+D13*(1-D20*0.5)) -> 0.08 | E27: =MAX(0,+E13*(1-E20*0.5)) -> 0.08 | F27: =MAX(0,+F13*(1-F20*0.5)) -> 0.08 | G27: =MAX(0,+G13*(1-G20*0.5)) -> 0.08 | H27: =MAX(0,+H13*(1-H20*0.5)) -> 0.08 | I27: =MAX(0,+I13*(1-I20*0.5)) -> 0.08 | J27: =MAX(0,+J13*(1-J20*0.5)) -> 0.08 | K27: =MAX(0,+K13*(1-K20*0.5)) -> 0.08 | ... O27: =MAX(0,+O13*(1-O20*0.5)) -> 0.08
B28: Nuevos
D29: =SUMPRODUCT(D25:D27,D39:D41)/SUM(D39:D41) -> 0.057398634 | E29: =SUMPRODUCT(E25:E27,E39:E41)/SUM(E39:E41) -> 0.056693341 | F29: =SUMPRODUCT(F25:F27,F39:F41)/SUM(F39:F41) -> 0.055976769 | G29: =SUMPRODUCT(G25:G27,G39:G41)/SUM(G39:G41) -> 0.055249515 | H29: =SUMPRODUCT(H25:H27,H39:H41)/SUM(H39:H41) -> 0.054512217 | I29: =SUMPRODUCT(I25:I27,I39:I41)/SUM(I39:I41) -> 0.053765562 | J29: =SUMPRODUCT(J25:J27,J39:J41)/SUM(J39:J41) -> 0.053010277 | K29: =SUMPRODUCT(K25:K27,K39:K41)/SUM(K39:K41) -> 0.052247132 | ... O29: =SUMPRODUCT(O25:O27,O39:O41)/SUM(O39:O41) -> 0.049132538
B31: Clientes Base | C31: Mes 0 | D31: Mes 1 | E31: Mes 2 | F31: Mes 3 | G31: Mes 4 | H31: Mes 5 | I31: Mes 6 | J31: Mes 7 | K31: Mes 8 | L31: Mes 9 | M31: Mes 10 | N31: Mes 11 | O31: Mes 12
B32: VIPs | C32: =+C5 -> 552631.58 | D32: =+C32*(1-D11) -> 544342.11 | E32: =+D32*(1-E11) -> 536176.97 | F32: =+E32*(1-F11) -> 528134.32 | G32: =+F32*(1-G11) -> 520212.3 | H32: =+G32*(1-H11) -> 512409.12 | I32: =+H32*(1-I11) -> 504722.98 | J32: =+I32*(1-J11) -> 497152.14 | K32: =+J32*(1-K11) -> 489694.86 | ... O32: =+N32*(1-O11) -> 460967.67
B33: Riesgo Fuga | C33: =+C6 -> 1105263.2 | D33: =+C33*(1-D12) -> 1038947.4 | E33: =+D33*(1-E12) -> 976610.53 | F33: =+E33*(1-F12) -> 918013.89 | G33: =+F33*(1-G12) -> 862933.06 | H33: =+G33*(1-H12) -> 811157.08 | I33: =+H33*(1-I12) -> 762487.65 | J33: =+I33*(1-J12) -> 716738.39 | K33: =+J33*(1-K12) -> 673734.09 | ... O33: =+N33*(1-O12) -> 526017.19
B34: Oportunistas | C34: =+C7 -> 1842105.3 | D34: =+C34*(1-D13) -> 1694736.8 | E34: =+D34*(1-E13) -> 1559157.9 | F34: =+E34*(1-F13) -> 1434425.3 | G34: =+F34*(1-G13) -> 1319671.2 | H34: =+G34*(1-H13) -> 1214097.5 | I34: =+H34*(1-I13) -> 1116969.7 | J34: =+I34*(1-J13) -> 1027612.2 | K34: =+J34*(1-K13) -> 945403.19 | ... O34: =+N34*(1-O13) -> 677280.19
B35: Nuevos
C36: =SUM(C32:C35) -> 3500000 | D36: =SUM(D32:D35) -> 3278026.3 | E36: =SUM(E32:E35) -> 3071945.4 | F36: =SUM(F32:F35) -> 2880573.5 | G36: =SUM(G32:G35) -> 2702816.6 | H36: =SUM(H32:H35) -> 2537663.7 | I36: =SUM(I32:I35) -> 2384180.4 | J36: =SUM(J32:J35) -> 2241502.7 | ... O36: =SUM(O32:O35) -> 1664265
B38: Clientes Finales | C38: Mes 0 | D38: Mes 1 | E38: Mes 2 | F38: Mes 3 | G38: Mes 4 | H38: Mes 5 | I38: Mes 6 | J38: Mes 7 | K38: Mes 8 | L38: Mes 9 | M38: Mes 10 | N38: Mes 11 | O38: Mes 12
B39: VIPs | C39: =+C5 -> 552631.58 | D39: =+C39*(1-D25) -> 546414.47 | E39: =+D39*(1-E25) -> 540267.31 | F39: =+E39*(1-F25) -> 534189.3 | G39: =+F39*(1-G25) -> 528179.67 | H39: =+G39*(1-H25) -> 522237.65 | I39: =+H39*(1-I25) -> 516362.48 | J39: =+I39*(1-J25) -> 510553.4 | K39: =+J39*(1-K25) -> 504809.68 | ... O39: =+N39*(1-O25) -> 482473.71 | P39: =+O39/C39-1 -> -0.12695233
B40: Riesgo Fuga | C40: =+C6 -> 1105263.2 | D40: =+C40*(1-D26) -> 1055526.3 | E40: =+D40*(1-E26) -> 1008027.6 | F40: =+E40*(1-F26) -> 962666.39 | G40: =+F40*(1-G26) -> 919346.4 | H40: =+G40*(1-H26) -> 877975.81 | I40: =+H40*(1-I26) -> 838466.9 | J40: =+I40*(1-J26) -> 800735.89 | K40: =+J40*(1-K26) -> 764702.78 | ... O40: =+N40*(1-O26) -> 636071.82 | P40: =+O40/C40-1 -> -0.42450645
B41: Oportunistas | C41: =+C7 -> 1842105.3 | D41: =+C41*(1-D27) -> 1694736.8 | E41: =+D41*(1-E27) -> 1559157.9 | F41: =+E41*(1-F27) -> 1434425.3 | G41: =+F41*(1-G27) -> 1319671.2 | H41: =+G41*(1-H27) -> 1214097.5 | I41: =+H41*(1-I27) -> 1116969.7 | J41: =+I41*(1-J27) -> 1027612.2 | K41: =+J41*(1-K27) -> 945403.19 | ... O41: =+N41*(1-O27) -> 677280.19 | P41: =+O41/C41-1 -> -0.63233361
B42: Nuevos | D42: 50000 | E42: 50000 | F42: 50000 | G42: 50000 | H42: 50000 | I42: 50000 | J42: 50000 | K42: 50000 | L42: 50000 | M42: 50000 | N42: 50000 | O42: 50000
B43: TOTAL | C43: =SUM(C39:C42) -> 3500000 | D43: =SUM(D39:D42) -> 3346677.6 | E43: =SUM(E39:E42) -> 3157452.8 | F43: =SUM(F39:F42) -> 2981281 | G43: =SUM(G39:G42) -> 2817197.3 | H43: =SUM(H39:H42) -> 2664311 | I43: =SUM(I39:I42) -> 2521799.1 | J43: =SUM(J39:J42) -> 2388901.5 | ... O43: =SUM(O39:O42) -> 1845825.7
B45: Revenue Incremental (ARS MM) | C45: Mes 0 | D45: Mes 1 | E45: Mes 2 | F45: Mes 3 | G45: Mes 4 | H45: Mes 5 | I45: Mes 6 | J45: Mes 7 | K45: Mes 8 | L45: Mes 9 | M45: Mes 10 | N45: Mes 11 | O45: Mes 12 | P45: Total
B46: VIPs | D46: =+((D39-C39)*$F5)/1000000+C46 -> -198.4127 | E46: =+((E39-D39)*$F5)/1000000+D46 -> -394.59325 | F46: =+((F39-E39)*$F5)/1000000+E46 -> -588.56678 | G46: =+((G39-F39)*$F5)/1000000+F46 -> -780.3581 | H46: =+((H39-G39)*$F5)/1000000+G46 -> -969.99177 | I46: =+((I39-H39)*$F5)/1000000+H46 -> -1157.4921 | J46: =+((J39-I39)*$F5)/1000000+I46 -> -1342.883 | K46: =+((K39-J39)*$F5)/1000000+J46 -> -1526.1882 | ... O46: =+((O39-N39)*$F5)/1000000+N46 -> -2239.0181 | P46: =SUM(D46:O46) -> -14855.394
B47: Riesgo Fuga | D47: =+((D40-C40)*$F6)/1000000+C47 -> -400 | E47: =+((E40-D40)*$F6)/1000000+D47 -> -782 | F47: =+((F40-E40)*$F6)/1000000+E47 -> -1146.81 | G47: =+((G40-F40)*$F6)/1000000+F47 -> -1495.2035 | H47: =+((H40-G40)*$F6)/1000000+G47 -> -1827.9194 | I47: =+((I40-H40)*$F6)/1000000+H47 -> -2145.663 | J47: =+((J40-I40)*$F6)/1000000+I47 -> -2449.1082 | K47: =+((K40-J40)*$F6)/1000000+J47 -> -2738.8983 | ... O47: =+((O40-N40)*$F6)/1000000+N47 -> -3773.3907 | P47: =SUM(D47:O47) -> -26586.931
B48: Oportunistas | D48: =+((D41-C41)*$F7)/1000000+C48 -> -282.18695 | E48: =+((E41-D41)*$F7)/1000000+D48 -> -541.79894 | F48: =+((F41-E41)*$F7)/1000000+E48 -> -780.64197 | G48: =+((G41-F41)*$F7)/1000000+F48 -> -1000.3776 | H48: =+((H41-G41)*$F7)/1000000+G48 -> -1202.5343 | I48: =+((I41-H41)*$F7)/1000000+H48 -> -1388.5185 | J48: =+((J41-I41)*$F7)/1000000+I48 -> -1559.624 | K48: =+((K41-J41)*$F7)/1000000+J48 -> -1717.041 | ... O48: =+((O41-N41)*$F7)/1000000+N48 -> -2230.4536 | P48: =SUM(D48:O48) -> -16677.825
...

Sheet 06_Red_CAPEX
B3: Simulador 5 - Red de PDV, Aperturas/Cierres y CAPEX
B5: Formato | C5: Zona | D5: PDV Iniciales | E5: Aperturas | F5: Cierres | G5: PDV Finales | H5: CAPEX Apertura (ARS MM) | I5: Ventas/PDV Mes (ARS MM)
B6: Flagship | C6: CABA | D6: 8 | E6: =+Q20 -> 3 | F6: =+Q48 -> 0 | G6: =SUM(D6:F6) -> 11 | H6: 5833.3333 | I6: 665
B7: Flagship | C7: GBA | D7: 6 | E7: =+Q21 -> 0 | F7: =+Q49 -> 0 | G7: =SUM(D7:F7) -> 6 | H7: 10320.513 | I7: 1092.5
B8: Standard | C8: CABA | D8: 20 | E8: =+Q22 -> 0 | F8: =+Q50 -> 0 | G8: =SUM(D8:F8) -> 20 | H8: 1125 | I8: 142.5
B9: Standard | C9: GBA | D9: 32 | E9: =+Q23 -> 0 | F9: =+Q51 -> 0 | G9: =SUM(D9:F9) -> 32 | H9: 2105.2632 | I9: 237.5
B10: Proximidad | C10: CABA | D10: 18 | E10: =+Q24 -> 0 | F10: =+Q52 -> 0 | G10: =SUM(D10:F10) -> 18 | H10: 600 | I10: 71.25
B11: Proximidad | C11: GBA | D11: 32 | E11: =+Q25 -> 0 | F11: =+Q53 -> -11 | G11: =SUM(D11:F11) -> 21 | H11: 1000 | I11: 118.75
B12: Hub/Dark Store | C12: CABA | D12: 1 | E12: =+Q26 -> 4 | F12: =+Q54 -> 0 | G12: =SUM(D12:F12) -> 5 | H12: 2000 | I12: 237.5
B13: Hub/Dark Store | C13: GBA | D13: 3 | E13: =+Q27 -> 4 | F13: =+Q55 -> 0 | G13: =SUM(D13:F13) -> 7 | H13: 2400 | I13: 285
B15: TOTAL | D15: =SUM(D6:D13) -> 120 | E15: =SUM(E6:E13) -> 11 | F15: =SUM(F6:F13) -> -11 | G15: =SUM(G6:G13) -> 120 | H15: =SUMPRODUCT(H6:H13,$D$6:$D$13)/$D$15 -> 2087.1514 | I15: =SUMPRODUCT(I6:I13,$D$6:$D$13)/$D$15 -> 237.5
B17: Aperturas # PDV
B19: Formato | C19: Zona | D19: Mes 0 | E19: Mes 1 | F19: Mes 2 | G19: Mes 3 | H19: Mes 4 | I19: Mes 5 | J19: Mes 6 | K19: Mes 7 | L19: Mes 8 | M19: Mes 9 | N19: Mes 10 | O19: Mes 11 | P19: Mes 12 | Q19: Total
B20: Flagship | C20: CABA | E20: 0 | F20: 0 | G20: 1 | H20: 0 | I20: 0 | J20: 0 | K20: 1 | L20: 0 | M20: 0 | N20: 1 | O20: 0 | P20: 0 | Q20: =SUM(E20:P20) -> 3
B21: Flagship | C21: GBA | E21: 0 | F21: 0 | G21: 0 | H21: 0 | I21: 0 | J21: 0 | K21: 0 | L21: 0 | M21: 0 | N21: 0 | O21: 0 | P21: 0 | Q21: =SUM(E21:P21) -> 0
B22: Standard | C22: CABA | E22: 0 | F22: 0 | G22: 0 | H22: 0 | I22: 0 | J22: 0 | K22: 0 | L22: 0 | M22: 0 | N22: 0 | O22: 0 | P22: 0 | Q22: =SUM(E22:P22) -> 0
B23: Standard | C23: GBA | E23: 0 | F23: 0 | G23: 0 | H23: 0 | I23: 0 | J23: 0 | K23: 0 | L23: 0 | M23: 0 | N23: 0 | O23: 0 | P23: 0 | Q23: =SUM(E23:P23) -> 0
B24: Proximidad | C24: CABA | E24: 0 | F24: 0 | G24: 0 | H24: 0 | I24: 0 | J24: 0 | K24: 0 | L24: 0 | M24: 0 | N24: 0 | O24: 0 | P24: 0 | Q24: =SUM(E24:P24) -> 0
B25: Proximidad | C25: GBA | E25: 0 | F25: 0 | G25: 0 | H25: 0 | I25: 0 | J25: 0 | K25: 0 | L25: 0 | M25: 0 | N25: 0 | O25: 0 | P25: 0 | Q25: =SUM(E25:P25) -> 0
B26: Hub/Dark Store | C26: CABA | E26: 0 | F26: 0 | G26: 0 | H26: 0 | I26: 0 | J26: 1 | K26: 0 | L26: 1 | M26: 0 | N26: 1 | O26: 0 | P26: 1 | Q26: =SUM(E26:P26) -> 4
B27: Hub/Dark Store | C27: GBA | E27: 0 | F27: 0 | G27: 0 | H27: 0 | I27: 0 | J27: 1 | K27: 0 | L27: 1 | M27: 0 | N27: 1 | O27: 0 | P27: 1 | Q27: =SUM(E27:P27) -> 4
B29: TOTAL | D29: =SUM(D20:D27) -> 0 | E29: =SUM(E20:E27) -> 0 | F29: =SUM(F20:F27) -> 0 | G29: =SUM(G20:G27) -> 1 | H29: =SUM(H20:H27) -> 0 | I29: =SUM(I20:I27) -> 0 | J29: =SUM(J20:J27) -> 2 | K29: =SUM(K20:K27) -> 1 | ... Q29: =SUM(Q20:Q27) -> 11
B31: Aperturas PDV (ARS MM)
B33: Formato | C33: Zona | D33: Mes 0 | E33: Mes 1 | F33: Mes 2 | G33: Mes 3 | H33: Mes 4 | I33: Mes 5 | J33: Mes 6 | K33: Mes 7 | L33: Mes 8 | M33: Mes 9 | N33: Mes 10 | O33: Mes 11 | P33: Mes 12 | Q33: Total
B34: Flagship | C34: CABA | E34: =+E20*$I6 -> 0 | F34: =+F20*$I6+E34 -> 0 | G34: =+G20*$I6+F34 -> 665 | H34: =+H20*$I6+G34 -> 665 | I34: =+I20*$I6+H34 -> 665 | J34: =+J20*$I6+I34 -> 665 | K34: =+K20*$I6+J34 -> 1330 | L34: =+L20*$I6+K34 -> 1330 | M34: =+M20*$I6+L34 -> 1330 | ... P34: =+P20*$I6+O34 -> 1995 | Q34: =SUM(E34:P34) -> 12635
B35: Flagship | C35: GBA | E35: =+E21*$I7 -> 0 | F35: =+F21*$I7+E35 -> 0 | G35: =+G21*$I7+F35 -> 0 | H35: =+H21*$I7+G35 -> 0 | I35: =+I21*$I7+H35 -> 0 | J35: =+J21*$I7+I35 -> 0 | K35: =+K21*$I7+J35 -> 0 | L35: =+L21*$I7+K35 -> 0 | M35: =+M21*$I7+L35 -> 0 | ... P35: =+P21*$I7+O35 -> 0 | Q35: =SUM(E35:P35) -> 0
B36: Standard | C36: CABA | E36: =+E22*$I8 -> 0 | F36: =+F22*$I8+E36 -> 0 | G36: =+G22*$I8+F36 -> 0 | H36: =+H22*$I8+G36 -> 0 | I36: =+I22*$I8+H36 -> 0 | J36: =+J22*$I8+I36 -> 0 | K36: =+K22*$I8+J36 -> 0 | L36: =+L22*$I8+K36 -> 0 | M36: =+M22*$I8+L36 -> 0 | ... P36: =+P22*$I8+O36 -> 0 | Q36: =SUM(E36:P36) -> 0
B37: Standard | C37: GBA | E37: =+E23*$I9 -> 0 | F37: =+F23*$I9+E37 -> 0 | G37: =+G23*$I9+F37 -> 0 | H37: =+H23*$I9+G37 -> 0 | I37: =+I23*$I9+H37 -> 0 | J37: =+J23*$I9+I37 -> 0 | K37: =+K23*$I9+J37 -> 0 | L37: =+L23*$I9+K37 -> 0 | M37: =+M23*$I9+L37 -> 0 | ... P37: =+P23*$I9+O37 -> 0 | Q37: =SUM(E37:P37) -> 0
B38: Proximidad | C38: CABA | E38: =+E24*$I10 -> 0 | F38: =+F24*$I10+E38 -> 0 | G38: =+G24*$I10+F38 -> 0 | H38: =+H24*$I10+G38 -> 0 | I38: =+I24*$I10+H38 -> 0 | J38: =+J24*$I10+I38 -> 0 | K38: =+K24*$I10+J38 -> 0 | L38: =+L24*$I10+K38 -> 0 | M38: =+M24*$I10+L38 -> 0 | ... P38: =+P24*$I10+O38 -> 0 | Q38: =SUM(E38:P38) -> 0
B39: Proximidad | C39: GBA | E39: =+E25*$I11 -> 0 | F39: =+F25*$I11+E39 -> 0 | G39: =+G25*$I11+F39 -> 0 | H39: =+H25*$I11+G39 -> 0 | I39: =+I25*$I11+H39 -> 0 | J39: =+J25*$I11+I39 -> 0 | K39: =+K25*$I11+J39 -> 0 | L39: =+L25*$I11+K39 -> 0 | M39: =+M25*$I11+L39 -> 0 | ... P39: =+P25*$I11+O39 -> 0 | Q39: =SUM(E39:P39) -> 0
B40: Hub/Dark Store | C40: CABA | E40: =+E26*$I12 -> 0 | F40: =+F26*$I12+E40 -> 0 | G40: =+G26*$I12+F40 -> 0 | H40: =+H26*$I12+G40 -> 0 | I40: =+I26*$I12+H40 -> 0 | J40: =+J26*$I12+I40 -> 237.5 | K40: =+K26*$I12+J40 -> 237.5 | L40: =+L26*$I12+K40 -> 475 | M40: =+M26*$I12+L40 -> 475 | ... P40: =+P26*$I12+O40 -> 950 | Q40: =SUM(E40:P40) -> 3800
B41: Hub/Dark Store | C41: GBA | E41: =+E27*$I13 -> 0 | F41: =+F27*$I13+E41 -> 0 | G41: =+G27*$I13+F41 -> 0 | H41: =+H27*$I13+G41 -> 0 | I41: =+I27*$I13+H41 -> 0 | J41: =+J27*$I13+I41 -> 285 | K41: =+K27*$I13+J41 -> 285 | L41: =+L27*$I13+K41 -> 570 | M41: =+M27*$I13+L41 -> 570 | ... P41: =+P27*$I13+O41 -> 1140 | Q41: =SUM(E41:P41) -> 4560
B43: TOTAL | D43: =SUM(D34:D41) -> 0 | E43: =SUM(E34:E41) -> 0 | F43: =SUM(F34:F41) -> 0 | G43: =SUM(G34:G41) -> 665 | H43: =SUM(H34:H41) -> 665 | I43: =SUM(I34:I41) -> 665 | J43: =SUM(J34:J41) -> 1187.5 | K43: =SUM(K34:K41) -> 1852.5 | ... Q43: =SUM(Q34:Q41) -> 20995
B45: Cierre # PDV
B47: Formato | C47: Zona | D47: Mes 0 | E47: Mes 1 | F47: Mes 2 | G47: Mes 3 | H47: Mes 4 | I47: Mes 5 | J47: Mes 6 | K47: Mes 7 | L47: Mes 8 | M47: Mes 9 | N47: Mes 10 | O47: Mes 11 | P47: Mes 12 | Q47: Total
B48: Flagship | C48: CABA | E48: 0 | F48: 0 | G48: 0 | H48: 0 | I48: 0 | J48: 0 | K48: 0 | L48: 0 | M48: 0 | N48: 0 | O48: 0 | P48: 0 | Q48: =SUM(E48:P48) -> 0
B49: Flagship | C49: GBA | E49: 0 | F49: 0 | G49: 0 | H49: 0 | I49: 0 | J49: 0 | K49: 0 | L49: 0 | M49: 0 | N49: 0 | O49: 0 | P49: 0 | Q49: =SUM(E49:P49) -> 0
B50: Standard | C50: CABA | E50: 0 | F50: 0 | G50: 0 | H50: 0 | I50: 0 | J50: 0 | K50: 0 | L50: 0 | M50: 0 | N50: 0 | O50: 0 | P50: 0 | Q50: =SUM(E50:P50) -> 0
B51: Standard | C51: GBA | E51: 0 | F51: 0 | G51: 0 | H51: 0 | I51: 0 | J51: 0 | K51: 0 | L51: 0 | M51: 0 | N51: 0 | O51: 0 | P51: 0 | Q51: =SUM(E51:P51) -> 0
B52: Proximidad | C52: CABA | E52: 0 | F52: 0 | G52: 0 | H52: 0 | I52: 0 | J52: 0 | K52: 0 | L52: 0 | M52: 0 | N52: 0 | O52: 0 | P52: 0 | Q52: =SUM(E52:P52) -> 0
...

Sheet 07_PL_TiposPDV
B3: P&L Base por Tipo de PDV y Zona
B5: Formato | C5: Zona | D5: Tiendas Finales | E5: Ventas Mensual | F5: Margen % | G5: Margen Bruto | H5: Merma | I5: Markteting | J5: Gastos Personal | K5: Alquileres | L5: G&A/Otros | M5: Logistica | N5: EBITDA | O5: EBITDA % | Q5: Gastos Personal | R5: Alquileres | S5: G&A/Otros | T5: Logistica
B6: ='06_Red_CAPEX'!B6 -> Flagship | C6: ='06_Red_CAPEX'!C6 -> CABA | D6: ='06_Red_CAPEX'!G6 -> 11 | E6: ='06_Red_CAPEX'!D6*'06_Red_CAPEX'!I6 -> 5320 | F6: 0.39 | G6: =E6*F6 -> 2074.8 | H6: =-E6*'08_Core_Financiero'!$AC$8 -> 55.86 | I6: =-E6*'08_Core_Financiero'!$AC$12 -> 76.841155 | J6: =+$E6*Q6 -> 691.6 | K6: =+$E6*R6 -> 186.2 | L6: =+$E6*S6 -> 345.8 | M6: =+$E6*T6 -> 145.22902 | N6: =G6-J6-K6-L6-M6-H6-I6 -> 573.26982 | O6: =N6/E6 -> 0.10775749 | Q6: 0.13 | R6: 0.035 | S6: 0.065 | T6: =+'04_Digital_Logistica'!$P$13 -> 0.027298688
B7: ='06_Red_CAPEX'!B7 -> Flagship | C7: ='06_Red_CAPEX'!C7 -> GBA | D7: ='06_Red_CAPEX'!G7 -> 6 | E7: ='06_Red_CAPEX'!D7*'06_Red_CAPEX'!I7 -> 6555 | F7: 0.355 | G7: =E7*F7 -> 2327.025 | H7: =-E7*'08_Core_Financiero'!$AC$8 -> 68.8275 | I7: =-E7*'08_Core_Financiero'!$AC$12 -> 94.67928 | J7: =+$E7*Q7 -> 786.6 | K7: =+$E7*R7 -> 163.875 | L7: =+$E7*S7 -> 360.525 | M7: =+$E7*T7 -> 178.9429 | N7: =G7-J7-K7-L7-M7-H7-I7 -> 673.57532 | O7: =N7/E7 -> 0.10275749 | Q7: 0.12 | R7: 0.025 | S7: 0.055 | T7: =+'04_Digital_Logistica'!$P$13 -> 0.027298688
B8: ='06_Red_CAPEX'!B8 -> Standard | C8: ='06_Red_CAPEX'!C8 -> CABA | D8: ='06_Red_CAPEX'!G8 -> 20 | E8: ='06_Red_CAPEX'!D8*'06_Red_CAPEX'!I8 -> 2850 | F8: 0.355 | G8: =E8*F8 -> 1011.75 | H8: =-E8*'08_Core_Financiero'!$AC$8 -> 29.925 | I8: =-E8*'08_Core_Financiero'!$AC$12 -> 41.164904 | J8: =+$E8*Q8 -> 413.25 | K8: =+$E8*R8 -> 128.25 | L8: =+$E8*S8 -> 213.75 | M8: =+$E8*T8 -> 77.801262 | N8: =G8-J8-K8-L8-M8-H8-I8 -> 107.60883 | O8: =N8/E8 -> 0.037757486 | Q8: =+Q6+0.015 -> 0.145 | R8: =+R6+0.01 -> 0.045 | S8: =+S6+0.01 -> 0.075 | T8: =+'04_Digital_Logistica'!$P$13 -> 0.027298688
B9: ='06_Red_CAPEX'!B9 -> Standard | C9: ='06_Red_CAPEX'!C9 -> GBA | D9: ='06_Red_CAPEX'!G9 -> 32 | E9: ='06_Red_CAPEX'!D9*'06_Red_CAPEX'!I9 -> 7600 | F9: 0.32 | G9: =E9*F9 -> 2432 | H9: =-E9*'08_Core_Financiero'!$AC$8 -> 79.8 | I9: =-E9*'08_Core_Financiero'!$AC$12 -> 109.77308 | J9: =+$E9*Q9 -> 1026 | K9: =+$E9*R9 -> 266 | L9: =+$E9*S9 -> 494 | M9: =+$E9*T9 -> 207.47003 | N9: =G9-J9-K9-L9-M9-H9-I9 -> 248.95689 | O9: =N9/E9 -> 0.032757486 | Q9: =+Q7+0.015 -> 0.135 | R9: =+R7+0.01 -> 0.035 | S9: =+S7+0.01 -> 0.065 | T9: =+'04_Digital_Logistica'!$P$13 -> 0.027298688
B10: ='06_Red_CAPEX'!B10 -> Proximidad | C10: ='06_Red_CAPEX'!C10 -> CABA | D10: ='06_Red_CAPEX'!G10 -> 18 | E10: ='06_Red_CAPEX'!D10*'06_Red_CAPEX'!I10 -> 1282.5 | F10: 0.34 | G10: =E10*F10 -> 436.05 | H10: =-E10*'08_Core_Financiero'!$AC$8 -> 13.46625 | I10: =-E10*'08_Core_Financiero'!$AC$12 -> 18.524207 | J10: =+$E10*Q10 -> 205.2 | K10: =+$E10*R10 -> 70.5375 | L10: =+$E10*S10 -> 109.0125 | M10: =+$E10*T10 -> 35.010568 | N10: =G10-J10-K10-L10-M10-H10-I10 -> -15.701025 | O10: =N10/E10 -> -0.012242514 | Q10: =+Q8+0.015 -> 0.16 | R10: =+R8+0.01 -> 0.055 | S10: =+S8+0.01 -> 0.085 | T10: =+'04_Digital_Logistica'!$P$13 -> 0.027298688
B11: ='06_Red_CAPEX'!B11 -> Proximidad | C11: ='06_Red_CAPEX'!C11 -> GBA | D11: ='06_Red_CAPEX'!G11 -> 21 | E11: ='06_Red_CAPEX'!D11*'06_Red_CAPEX'!I11 -> 3800 | F11: 0.295 | G11: =E11*F11 -> 1121 | H11: =-E11*'08_Core_Financiero'!$AC$8 -> 39.9 | I11: =-E11*'08_Core_Financiero'!$AC$12 -> 54.886539 | J11: =+$E11*Q11 -> 570 | K11: =+$E11*R11 -> 171 | L11: =+$E11*S11 -> 285 | M11: =+$E11*T11 -> 103.73502 | N11: =G11-J11-K11-L11-M11-H11-I11 -> -103.52155 | O11: =N11/E11 -> -0.027242514 | Q11: =+Q9+0.015 -> 0.15 | R11: =+R9+0.01 -> 0.045 | S11: =+S9+0.01 -> 0.075 | T11: =+'04_Digital_Logistica'!$P$13 -> 0.027298688
B12: ='06_Red_CAPEX'!B12 -> Hub/Dark Store | C12: ='06_Red_CAPEX'!C12 -> CABA | D12: ='06_Red_CAPEX'!G12 -> 5 | E12: ='06_Red_CAPEX'!D12*'06_Red_CAPEX'!I12 -> 237.5 | F12: 0.32 | G12: =E12*F12 -> 76 | H12: =-E12*'08_Core_Financiero'!$AC$8 -> 2.49375 | I12: =-E12*'08_Core_Financiero'!$AC$12 -> 3.4304087 | J12: =+$E12*Q12 -> 23.75 | K12: =+$E12*R12 -> 4.75 | L12: =+$E12*S12 -> 9.5 | M12: =+$E12*T12 -> 20.1875 | N12: =G12-J12-K12-L12-M12-H12-I12 -> 11.888341 | O12: =N12/E12 -> 0.050056174 | Q12: 0.1 | R12: 0.02 | S12: 0.04 | T12: =+'04_Digital_Logistica'!$P$10 -> 0.085
B13: ='06_Red_CAPEX'!B13 -> Hub/Dark Store | C13: ='06_Red_CAPEX'!C13 -> GBA | D13: ='06_Red_CAPEX'!G13 -> 7 | E13: ='06_Red_CAPEX'!D13*'06_Red_CAPEX'!I13 -> 855 | F13: 0.31 | G13: =E13*F13 -> 265.05 | H13: =-E13*'08_Core_Financiero'!$AC$8 -> 8.9775 | I13: =-E13*'08_Core_Financiero'!$AC$12 -> 12.349471 | J13: =+$E13*Q13 -> 85.5 | K13: =+$E13*R13 -> 17.1 | L13: =+$E13*S13 -> 25.65 | M13: =+$E13*T13 -> 72.675 | N13: =G13-J13-K13-L13-M13-H13-I13 -> 42.798029 | O13: =N13/E13 -> 0.050056174 | Q13: 0.1 | R13: 0.02 | S13: 0.03 | T13: =+'04_Digital_Logistica'!$P$10 -> 0.085
B14: TOTAL | D14: =SUM(D6:D13) -> 120 | E14: =SUM(E6:E13) -> 28500 | F14: =SUMPRODUCT(F6:F13,E6:E13)/SUM(E6:E13) -> 0.34188333 | G14: =SUM(G6:G13) -> 9743.675 | H14: =SUM(H6:H13) -> 299.25 | I14: =SUM(I6:I13) -> 411.64904 | J14: =SUM(J6:J13) -> 3801.9 | K14: =SUM(K6:K13) -> 1007.7125 | L14: =SUM(L6:L13) -> 1843.2375 | M14: =SUM(M6:M13) -> 841.0513 | N14: =SUM(N6:N13) -> 1538.8747 | O14: =N14/E14 -> 0.053995602 | Q14: =SUMPRODUCT(Q6:Q13,$E$6:$E$13)/$E$14 -> 0.1334 | R14: =SUMPRODUCT(R6:R13,$E$6:$E$13)/$E$14 -> 0.035358333 | S14: =SUMPRODUCT(S6:S13,$E$6:$E$13)/$E$14 -> 0.064675 | T14: =SUMPRODUCT(T6:T13,$E$6:$E$13)/$E$14 -> 0.029510572
F15: =+'02_Pricing'!Q18 -> 0 | G15: =+G14/$E$14 -> 0.34188333 | H15: =+H14/$E$14 -> 0.0105 | I15: =+I14/$E$14 -> 0.014443826 | J15: =+J14/$E$14 -> 0.1334 | K15: =+K14/$E$14 -> 0.035358333 | L15: =+L14/$E$14 -> 0.064675 | M15: =+M14/$E$14 -> 0.029510572 | N15: =+N14/$E$14 -> 0.053995602
B18: Revenue Teórico | D18: Mes 0 | E18: Mes 1 | F18: Mes 2 | G18: Mes 3 | H18: Mes 4 | I18: Mes 5 | J18: Mes 6 | K18: Mes 7 | L18: Mes 8 | M18: Mes 9 | N18: Mes 10 | O18: Mes 11 | P18: Mes 12 | Q18: Total
